pressure plate routine error when contacting simulator:

Task exception was never retrieved
future: <Task finished coro=<process_message() done, defined at C:/Users/sjoer/Desktop/Controller/Resources/entrypoint.py:71> exception=JSONDecodeError('Expecting value: line 1 column 8 (char 7)',)>
Traceback (most recent call last):
  File "C:/Users/sjoer/Desktop/Controller/Resources/entrypoint.py", line 75, in process_message
    data = json.loads(message)
  File "C:\Users\sjoer\AppData\Local\Programs\Python\Python36\lib\json\__init__.py", line 354, in loads
    return _default_decoder.decode(s)
  File "C:\Users\sjoer\AppData\Local\Programs\Python\Python36\lib\json\decoder.py", line 339, in decode
    obj, end = self.raw_decode(s, idx=_w(s, 0).end())
  File "C:\Users\sjoer\AppData\Local\Programs\Python\Python36\lib\json\decoder.py", line 357, in raw_decode
    raise JSONDecodeError("Expecting value", s, err.value) from None
json.decoder.JSONDecodeError: Expecting value: line 1 column 8 (char 7)

Test met DaniÃ«l:

Task exception was never retrieved
future: <Task finished coro=<process_message() done, defined at C:/Users/sjoer/Desktop/Controller/Resources/entrypoint.py:72> exception=AttributeError("'str' object has no attribute 'decode'",)>
Traceback (most recent call last):
  File "C:/Users/sjoer/Desktop/Controller/Resources/entrypoint.py", line 76, in process_message
    data = json.loads(message.decode('utf-8'))
AttributeError: 'str' object has no attribute 'decode'

Test met Jeffrey:
server - received solicited pong: 2b54b8d4